Workbook

Sheet ASS June2017
A1: GROUND WATER POTENTIAL OF PEESANGAN GW CLUSTER OF DISTRICT: AJMER AS ON JUNE 2017 | Q1: GROUND WATER POTENTIAL OF PEESANGAN GW CLUSTER OF DISTRICT: AJMER AS ON JUNE 2017 | AG1: GROUND WATER POTENTIAL OF PEESANGAN GW CLUSTER OF DISTRICT: AJMER AS ON JUNE 2017 | AW1: GROUND WATER POTENTIAL OF PEESANGAN GW CLUSTER OF DISTRICT: AJMER AS ON JUNE 2017 | BM1: GROUND WATER POTENTIAL OF PEESANGAN GW CLUSTER OF DISTRICT: AJMER AS ON JUNE 2017
A2: ESTIMATION OF GROUND WATER RECHARGE IN MONSOON PERIOD BY WATER TABLE FLUCTUATION METHOD | Q2: ESTIMATION OF GROUND WATER RECHARGE IN MONSOON PERIOD | AG2: NONMONSOONAL RECHARGE BY R.I.F. APPROACH AND BY OTHER SOURCES AND ANNUAL GROUND WATER AVAILABILITY | AW2: GROUND WATER RECHARGE,EXTRACTION & STAGE OF GROUND WATER DEVELOPMENT | BM2: GROUND WATER RECHARGE,EXTRACTION & STAGE OF GROUND WATER DEVELOPMENT
A4: Year | B4: Potential zone area | C4: Water Level Fluctuation | D4: Specific Yield | E4: Gross Kharif Draft (Agr.+ Dom.) | F4: Monsoon Recharge from Ground water Irrig. ( Rgw) | G4: Monsoon Recharge from canal (Rc) | H4: Monsoon Recharge from SWI (Rsw) | I4: Monsoon Recharge from Tanks & Ponds (Rt) | J4: Rainfall Recharge (Ri) | K4: Gross Agriculture Draft* | L4: Gross Domestic Draft | M4: Normal Monsoon Rainfall ( r ) | N4: Monsoon Rainfall (ri) | O4: Rainfall * Rainfall Monsoon (ri*ri) | P4: Monsoon Rainfall* Recharge (ri*Ri*) | Q4: Block | R4: Type of Area | S4: Potential Zone | T4: S1 (Sum of Rainfall in Monsoon) | U4: S2 (Sum of Rainfall Recharge in Monsoon) | V4: S3 (Sum of Rainfall* Rainfall Monsoon) | W4: S4 (Sum of Monsoon Rainfall* Recharge) | X4: (a) (Constant) | Y4: (b) (Constant) | Z4: Rrf normal (Linear regression method (a*x+b) | AA4: R.I. Factor | AB4: Monsoon Recharge Rrf (Normal rifm) | AC4: (PD)(percentage deviation) | AD4: Accepted Value of Monsoon Rainfall recharge Rrf (Normal) | AE4: Total Recharge from other sources | AF4: Total recharge during monsoon season R (normal) | AG4: Block | AH4: Type of Area | AI4: Potential zone | AJ4: Potential Zone area | AK4: R.I Factor | AL4: Normal Non-monsoon rainfall | AM4: Normal Annual Rainfall | AN4: Recharge from Rainfall during non-monsoon | AO4: Recharge from ground water irrigation (Rgw) | AP4: Non monsoon recharge from canal (Rc) | AQ4: Non- monsoon Recharge from SWI (Rsw) | AR4: Non- monsoon Recharge from Tanks & Ponds (Rt) | AS4: Recharge from other sources (Rgw+Rc+Rsw+Rt) | AT4: Total Recharge in Non- monsoon season | AU4: Total Annual ground water Recharge | AV4: Natural Discharge during non- monsoon season | AW4: Block | AX4: Area of Block | AY4: Type of Area | AZ4: Potential zone | BA4: Potential zone area | BB4: Net Annual Ground Water Availability | BC4: Existing Gross Ground Water Draft for Irrigation | BD4: Existing Gross G.W. Draft for Dom. & Ind. Use | BE4: Existing Gross Ground Water Draft for all uses | BF4: Allocation for Dom. & Ind. Requirement for 2025 | BG4: Net G.W. Availability for future Irr. Dev. | BH4: Stage of G.W. Develop- ment. | BI4: Whether significant decline in Pre monsoon W.L. | BJ4: Whether significant decline in post monsoon W.L. | BK4: Category | BL4: Annual Potential Recharge (mcm) | BM4: Block | BN4: Area of Block | BO4: Type of Area | BP4: Potential zone | BQ4: Potential zone area | BR4: Total Annual ground water Recharge | BS4: Natural Discharge during non- monsoon season | BT4: Net Annual Ground Water Availability | BU4: Existing Gross Ground Water Draft for Irrigation | BV4: Existing Gross G.W. Draft for Dom. & Ind. Use | BW4: Existing Gross Ground Water Draft for all uses | BX4: Allocation for Dom. & Ind. Requirement for 2025 | BY4: Net G.W. Availability for future Irr. Dev. | BZ4: Stage of G.W. Develop- ment. | CA4: Whether significant decline in Pre monsoon W.L. | CB4: Whether significant decline in post monsoon W.L. | CC4: Category
B5: (Sq.Km.) | C5: (m) | D5: (%) | E5: (mcm) | F5: (mcm) | G5: (mcm) | H5: (mcm) | I5: (mcm) | J5: (mcm) | K5: (mcm) | M5: (m) | N5: (m) | T5: (m) | U5: (mcm) | V5: (mcm) | W5: (mcm) | AB5: (mcm) | AC5: (%) | AD5: (mcm) | AE5: (mcm) | AJ5: (Sq.Km.) | AL5: (m) | AM5: (m) | AN5: (mcm) | AO5: (mcm) | AP5: (mcm) | AQ5: (mcm) | AR5: (mcm) | AS5: (mcm) | AT5: (mcm) | AU5: (mcm) | AV5: ( mcm ) | AX5: (Sq.Km.) | BA5: (Sq.kms) | BB5: (mcm) | BC5: (mcm) | BD5: (mcm) | BE5: (mcm) | BF5: (mcm) | BG5: (mcm) | BH5: (%) | BI5: (Yes/No) | BJ5: (Yes/No) | BN5: (Sq.Km.) | BQ5: (Sq.kms) | BR5: (mcm) | BS5: ( mcm ) | BT5: (mcm) | BU5: (mcm) | BV5: (mcm) | BW5: (mcm) | BX5: (mcm) | BY5: (mcm) | BZ5: (%) | CA5: (Yes/No) | CB5: (Yes/No)
A6: 1 | B6: 2 | C6: 3 | D6: 4 | E6: 5 | F6: 6 | G6: 7 | H6: 8 | I6: 9 | J6: 10 | K6: 11 | L6: 12 | M6: 13 | N6: 14 | O6: 15 | P6: 16 | Q6: 17 | R6: 18 | S6: 19 | T6: 20 | U6: 21 | V6: 22 | W6: 23 | X6: 24 | Y6: 25 | Z6: 26 | AA6: 27 | AB6: 28 | AC6: 29 | AD6: 30 | AE6: 31 | AF6: 32 | AG6: 33 | AH6: 34 | AI6: 35 | AJ6: 36 | AK6: 37 | AL6: 38 | AM6: 39 | AN6: 40 | AO6: 41 | AP6: 42 | AQ6: 43 | AR6: 44 | AS6: 45 | AT6: 46 | AU6: 47 | AV6: 48 | AW6: 49 | AX6: 50 | AY6: 51 | AZ6: 52 | BA6: 53 | BB6: 54 | BC6: 55 | BD6: 56 | BE6: 57 | BF6: 58 | BG6: 59 | BH6: 60 | BI6: 61 | BJ6: 62 | BK6: 63 | BL6: 64 | BM6: 1 | BN6: 2 | BO6: 3 | BP6: 4 | BQ6: 5 | BR6: 6 | BS6: 7 | BT6: 8 | BU6: 9 | BV6: 10 | BW6: 11 | BX6: 12 | BY6: 13 | BZ6: 14 | CA6: 15 | CB6: 16 | CC6: 17
A7: PEESANGAN GW CLUSTER
A8: 2012 | B8: 318.25 | C8: ='WaterLevel 12-16'!I88 -> 2.4505882 | D8: 0.12 | E8: =SUM(ROUND(K8*0.25,4),ROUND(L8*120/365,4)) -> 15.4355 | F8: =ROUND((K8*0.25)*0.15,4) -> 2.0693 | I8: 0.5252 | J8: =ROUND(((B8*C8*D8)+(E8-F8-I8-G8-H8)),4) -> 106.429 | K8: 55.18 | L8: 4.99 | M8: =NormalRF!C6*0.001 -> 0.39302 | N8: ='MonthlyRF n'!F23*0.001 -> 0.577 | O8: =(N8*N8) -> 0.332929 | P8: =ROUND(J8*N8,4) -> 61.4095 | Q8: =A7 -> PEESANGAN GW CLUSTER | R8: NC | S8: A | T8: =SUM(N8:N12) -> 2.5715 | U8: =SUM(J8:J12) -> 329.1168 | V8: =SUM(O8:O12) -> 1.3887978 | W8: =SUM(P8:P12) -> 184.7602 | X8: =(5*W8-(T8*U8))/(5*V8-(T8*T8)) -> 233.80399 | Y8: =(U8-(X8*T8))/5 -> -54.422033 | Z8: =ROUND(X8*M12+Y8,4) -> 39.9109 | AA8: 0.12 | AB8: =ROUND(AA8*M12*B12,4) -> 15.4085 | AC8: =((Z8-AB8)*100)/AB8 -> 159.01872 | AD8: =IF(AC8<-20,AB8*0.8,IF(AC8>20,AB8*1.2,Z8)) -> 18.4902 | AE8: =(F12+G12+H12+I12) -> 2.5596186 | AF8: =(+AD8+AE8) -> 21.049819 | AG8: =Q8 -> PEESANGAN GW CLUSTER | AH8: NC | AI8: A | AJ8: =B12 -> 318.25 | AK8: =AA8 -> 0.12 | AL8: =NormalRF!M6/1000 -> 0.04058 | AM8: =M12+AL8 -> 0.44405 | AN8: =IF(AL8>0.1*AM8,AJ8*AK8*AL8,0) -> 0 | AO8: =K12*0.75*0.15 -> 6.0195925 | AP8: 0 | AQ8: 0 | AR8: ='Seep-Tank-III'!H50 -> 0.9218643 | AS8: =SUM(AO8:AR8) -> 6.9414568 | AT8: =(AN8+AS8) -> 6.9414568 | AU8: =(AF8+AT8) -> 27.991275 | AV8: =ROUND(AU8*0.1,4) -> 2.7991 | AW8: =Q8 -> PEESANGAN GW CLUSTER | AX8: =AJ8 -> 318.25 | AY8: =AH8 -> NC | AZ8: =AI8 -> A | BA8: =B8 -> 318.25 | BB8: =(AU8-AV8) -> 25.192175 | BC8: =Compar!Q8 -> 53.507489 | BD8: =Compar!O8 -> 6.356475 | BE8: =(BC8+BD8) -> 59.863964 | BF8: ='Projected Cal. '!E14 -> 7.4871 | BG8: =BB8-BF8 -> 17.705075 | BH8: =ROUND((BE8*100)/BB8,2) -> 237.63 | BI8: ='Trend '!H16 -> YES | BJ8: ='Trend '!I16 -> YES | BK8: =IF(BH8<=70,"SAFE",IF(BH8<=90,"SEMICRITICAL",IF(BH8<=100,"CRITICAL","OVER EXPLO."))) -> OVER EXPLO. | BL8: 0 | BM8: =AW8 -> PEESANGAN GW CLUSTER | BN8: =AX8 -> 318.25 | BO8: =AY8 -> NC | BP8: =AZ8 -> A | BQ8: =BA8 -> 318.25 | BR8: =AU8 -> 27.991275 | BS8: =AV8 -> 2.7991 | BT8: =BB8 -> 25.192175 | BU8: =BC8 -> 53.507489 | BV8: =BD8 -> 6.356475 | BW8: =BE8 -> 59.863964 | BX8: ='Projected Cal. '!E14 -> 7.4871 | BY8: =BT8-BX8 -> 17.705075 | BZ8: =BH8 -> 237.63 | CA8: =BI8 -> YES | CB8: =BJ8 -> YES | CC8: =BK8 -> OVER EXPLO.
A9: 2013 | B9: 318.25 | C9: ='WaterLevel 12-16'!L88 -> 0.18411765 | D9: 0.12 | E9: =SUM(ROUND(K9*0.25,4),ROUND(L9*120/365,4)) -> 15.8377 | F9: =ROUND((K9*0.25)*0.15,4) -> 2.0985 | I9: 0.3664 | J9: =ROUND(((B9*C9*D9)+(E9-F9-I9-G9-H9)),4) -> 20.4043 | K9: 55.96 | L9: 5.62 | M9: =NormalRF!E6*0.001 -> 0.3935 | N9: ='MonthlyRF n'!F24*0.001 -> 0.4025 | O9: =(N9*N9) -> 0.16200625 | P9: =ROUND(J9*N9,4) -> 8.2127
A10: 2014 | B10: 318.25 | C10: ='WaterLevel 12-16'!O88 -> 1.6247059 | D10: 0.12 | E10: =SUM(ROUND(K10*0.25,4),ROUND(L10*120/365,4)) -> 16.0672 | F10: =ROUND((K10*0.25)*0.05,4) -> 0.7064 | I10: 0.5772 | J10: =ROUND(((B10*C10*D10)+(E10-F10-I10-G10-H10)),4) -> 76.8311 | K10: 56.51 | L10: 5.9 | M10: =NormalRF!G6*0.001 -> 0.39893 | N10: ='MonthlyRF n'!F25*0.001 -> 0.634 | O10: =(N10*N10) -> 0.401956 | P10: =ROUND(J10*N10,4) -> 48.7109 | BV10: for next 25 years | BX10: ='Projected Cal. '!E30 -> 10.0341
A11: 2015 | B11: 318.25 | C11: ='WaterLevel 12-16'!R88 -> 0.6325 | D11: 0.12 | E11: =SUM(ROUND(K11*0.25,4),ROUND(L11*120/365,4)) -> 16.3935 | F11: =ROUND((K11*0.25)*0.15,4) -> 2.1548 | I11: 0.3191 | J11: =ROUND(((B11*C11*D11)+(E11-F11-I11-G11-H11)),4) -> 38.0748 | K11: 57.46 | L11: 6.17 | M11: =NormalRF!I6*0.001 -> 0.39903 | N11: ='MonthlyRF n'!F26*0.001 -> 0.3505 | O11: =(N11*N11) -> 0.12285025 | P11: =ROUND(J11*N11,4) -> 13.3452 | BV11: For the year 2025 | BX11: ='Projected Cal. '!E14 -> 7.4871
A12: 2016 | B12: 318.25 | C12: ='WaterLevel 12-16'!U88 -> 1.95 | D12: 0.12 | E12: =SUM(ROUND(K12*0.25,4),ROUND(L12*120/365,4)) -> 15.4667 | F12: =ROUND((K12*0.25)*0.15,4) -> 2.0065 | I12: ='Seep-Tank-III'!I50 -> 0.55311858 | J12: =ROUND(((B12*C12*D12)+(E12-F12-I12-G12-H12)),4) -> 87.3776 | K12: =Compar!Q8 -> 53.507489 | L12: ='Dom Draft IV'!J136 -> 6.356475 | M12: =NormalRF!K6*0.001 -> 0.40347 | N12: ='MonthlyRF n'!F27*0.001 -> 0.6075 | O12: =(N12*N12) -> 0.36905625 | P12: =ROUND(J12*N12,4) -> 53.0819
A14: Note * : Peesangan Block is notified by the CGWA since 2011

Sheet irr. pot.
A1: TABLE - : IRRIGATION POTENTIAL OF PEESANGAN GW CLUSTER (JUNE 2017)
A2: Sr. No. | B2: Block | C2: Net Available Ground water Recharge (Ha.m/Yr) | D2: Net Irrigation Requirement (m) | E2: Ground Water Draft for Irrigation (ha.m/Yr) | F2: Irrigation Potential Created (ha) [col.5/4] | G2: Allocation of Domestic and Industrial need for the Year 2025 (ha.m/yr) | H2: Ground Water Balance (ha.m) [Col.3-5-7] | I2: Balance Irrigation Potential from Ground Water (ha) [Col.8/4] | J2: Ultimate Irrigation Potential from Ground water (ha) [Col.6+9]
A3: 1 | B3: 2 | C3: 3 | D3: 4 | E3: 5 | F3: 6 | G3: 7 | H3: 8 | I3: 9 | J3: 10
A4: 1 | B4: Peesangan GW Cluster | C4: ='ASS June2017'!BT8*100 -> 2519.2175 | D4: 0.55 | E4: ='ASS June2017'!BU8*100 -> 5350.7489 | F4: =E4/D4 -> 9728.6344 | G4: ='ASS June2017'!BF8*100 -> 748.71 | H4: =C4-E4-G4 -> -3580.2414 | I4: =H4/D4 -> -6509.5298 | J4: =F4+I4 -> 3219.1046
A6: Source: Data as per the Detailed Hydrogeological Survey of 100% GW extraction Units falls under aquifer boundary being conducted during March - April 2017 by CA Arpan Seva Sansthan under RACP

Sheet Rech-Tank-II
B1: TABLE-II : RECAHRGE FROM SURFACE WATER IRRIGATION BY TANKS & PONDS FOR THE YEAR 2016 OF PEESANGAN GW CLUSTER AJMER DISTRICT
A3: S. No. | B3: Name of village | C3: Zone | D3: Hydrogeological Formation | E3: Crop Type | F3: Irrigated Area (Sq.Km) By Tanks & Canal IRRIGATED AREA IN SQ.KM. | G3: Average Depth of Water Applied (m) | H3: Total water applied (mcm) | I3: Seepage Factor | J3: Non-Monsoon Seepage (mcm) | K3: Total Seepage (mcm)
A4: 1 | B4: 2 | C4: 3 | D4: 4 | E4: 5 | F4: 6 | G4: 7 | H4: 8 | I4: 9 | J4: 10 | K4: 11
A5: 1 | B5: Ambamassena | C5: A | D5: ALLUVIUM | E5: RABI | F5: 0.181 | G5: 0.2 | H5: =F5*G5 -> 0.0362 | I5: 0.3 | J5: _ | K5: =H5*I5 -> 0.01086
A6: 2 | B6: Ambamassena | C6: A | D6: ALLUVIUM | E6: RABI | F6: 0.181 | G6: 0.2 | H6: =F6*G6 -> 0.0362 | I6: 0.3 | J6: _ | K6: =H6*I6 -> 0.01086
A7: 3 | B7: Bhagwanpura | C7: A | D7: ALLUVIUM | E7: RABI | F7: 0.1086 | G7: 0.2 | H7: =F7*G7 -> 0.02172 | I7: 0.3 | J7: _ | K7: =H7*I7 -> 0.006516
A8: 4 | B8: Bhanwta | C8: A | D8: ALLUVIUM | E8: RABI | F8: 0.0113125 | G8: 0.2 | H8: =F8*G8 -> 0.0022625 | I8: 0.3 | J8: _ | K8: =H8*I8 -> 0.00067875
A9: 5 | B9: Bhanwta | C9: A | D9: ALLUVIUM | E9: RABI | F9: 0.0113125 | G9: 0.2 | H9: =F9*G9 -> 0.0022625 | I9: 0.3 | J9: _ | K9: =H9*I9 -> 0.00067875
A10: 6 | B10: Dantra | C10: A | D10: ALLUVIUM | E10: RABI | F10: 0.181 | G10: 0.2 | H10: =F10*G10 -> 0.0362 | I10: 0.3 | J10: _ | K10: =H10*I10 -> 0.01086
A11: 7 | B11: Dev Nagar | C11: A | D11: ALLUVIUM | E11: RABI | F11: 0.0040725 | G11: 0.2 | H11: =F11*G11 -> 0.0008145 | I11: 0.3 | K11: =H11*I11 -> 0.00024435
A12: 8 | B12: Dodiyana | C12: A | D12: ALLUVIUM | E12: RABI | F12: 0.1629 | G12: 0.2 | H12: =F12*G12 -> 0.03258 | I12: 0.3 | J12: _ | K12: =H12*I12 -> 0.009774
A13: 9 | B13: Ganahera | C13: A | D13: ALLUVIUM | E13: RABI | F13: 0.1991 | G13: 0.2 | H13: =F13*G13 -> 0.03982 | I13: 0.3 | J13: _ | K13: =H13*I13 -> 0.011946
A14: 10 | B14: Ganahera | C14: A | D14: ALLUVIUM | E14: RABI | F14: 0.181 | G14: 0.2 | H14: =F14*G14 -> 0.0362 | I14: 0.3 | J14: _ | K14: =H14*I14 -> 0.01086
A15: 11 | B15: Govindgarh | C15: A | D15: ALLUVIUM | E15: RABI | F15: 0.1991 | G15: 0.2 | H15: =F15*G15 -> 0.03982 | I15: 0.3 | K15: =H15*I15 -> 0.011946
A16: 12 | B16: Govindgarh | C16: A | D16: ALLUVIUM | E16: RABI | F16: 0.001086 | G16: 0.2 | H16: =F16*G16 -> 0.0002172 | I16: 0.3 | J16: _ | K16: =H16*I16 -> 6.516e-05
A17: 13 | B17: Kadel | C17: A | D17: ALLUVIUM | E17: RABI | F17: 0.1448 | G17: 0.2 | H17: =F17*G17 -> 0.02896 | I17: 0.3 | J17: _ | K17: =H17*I17 -> 0.008688
A18: 14 | B18: Kadel | C18: A | D18: ALLUVIUM | E18: RABI | F18: 0.1629 | G18: 0.2 | H18: =F18*G18 -> 0.03258 | I18: 0.3 | J18: _ | K18: =H18*I18 -> 0.009774
A19: 15 | B19: Kadel | C19: A | D19: ALLUVIUM | E19: RABI | F19: 0.181 | G19: 0.2 | H19: =F19*G19 -> 0.0362 | I19: 0.3 | J19: _ | K19: =H19*I19 -> 0.01086
A20: 16 | B20: Kadel | C20: A | D20: ALLUVIUM | E20: RABI | F20: 0.181 | G20: 0.2 | H20: =F20*G20 -> 0.0362 | I20: 0.3 | J20: _ | K20: =H20*I20 -> 0.01086
A21: 17 | B21: Kadel | C21: A | D21: ALLUVIUM | E21: RABI | F21: 0.1448 | G21: 0.2 | H21: =F21*G21 -> 0.02896 | I21: 0.3 | J21: _ | K21: =H21*I21 -> 0.008688
A22: 18 | B22: Kadel | C22: A | D22: ALLUVIUM | E22: RABI | F22: 0.1629 | G22: 0.2 | H22: =F22*G22 -> 0.03258 | I22: 0.3 | J22: _ | K22: =H22*I22 -> 0.009774
A23: 19 | B23: Kalesara | C23: A | D23: ALLUVIUM | E23: RABI | F23: 0.181 | G23: 0.2 | H23: =F23*G23 -> 0.0362 | I23: 0.3 | J23: _ | K23: =H23*I23 -> 0.01086
A24: 20 | B24: Khori | C24: A | D24: ALLUVIUM | E24: RABI | F24: 0.1991 | G24: 0.2 | H24: =F24*G24 -> 0.03982 | I24: 0.3 | J24: _ | K24: =H24*I24 -> 0.011946
A25: 21 | B25: Kishanpura | C25: A | D25: ALLUVIUM | E25: RABI | F25: 0.0011584 | G25: 0.2 | H25: =F25*G25 -> 0.00023168 | I25: 0.3 | J25: _ | K25: =H25*I25 -> 6.9504e-05
A26: 22 | B26: Kishanpura Goyla | C26: A | D26: ALLUVIUM | E26: RABI | F26: 0.1448 | G26: 0.2 | H26: =F26*G26 -> 0.02896 | I26: 0.3 | J26: _ | K26: =H26*I26 -> 0.008688
A27: 23 | B27: Majhewla | C27: A | D27: ALLUVIUM | E27: RABI | F27: 0.0113125 | G27: 0.2 | H27: =F27*G27 -> 0.0022625 | I27: 0.3 | J27: _ | K27: =H27*I27 -> 0.00067875
... A48: 44 | B48: Tilora | C48: A | D48: ALLUVIUM | E48: RABI | F48: 0.181 | G48: 0.2 | H48: =F48*G48 -> 0.0362 | I48: 0.3 | J48: _ | K48: =H48*I48 -> 0.01086
F49: 5.0948423
A50: Source: Data as per the Detailed Hydrogeological Survey of 100% GW extraction Units falls under aquifer boundary being conducted during March - April 2017 by CA Arpan Seva Sansthan under RACP

Sheet Seep-Tank-III
A1: TABLE : III - ESTIMATION OF SEEPAGE FROM TANKS
A3: Sr. No. | B3: Village | C3: Potential Zone | D3: Number of Tanks | E3: Total Water Spread Area (Sq.Km.) | F3: Seepage Factor 1.4mm/day | G3: Total Yearly Seepage 240 days (mcm) | H3: Seepage in Non-monsoon period (150 days) (mcm) | I3: Monsoon Seepage 90 days (mcm)
A4: 1 | B4: 2 | C4: 3 | D4: 4 | E4: 5 | F4: 6 | G4: 7 | H4: 8 | I4: 9
A5: 1 | B5: Ambamassena | C5: A | D5: 1 | E5: 0.1 | F5: 1.4 | G5: =SUM((E5*F5)*(240))/1000 -> 0.0336 | H5: =SUM((E5*F5)*(150))/1000 -> 0.021 | I5: =G5-H5 -> 0.0126
A6: 2 | B6: Ambamassena | C6: A | D6: 1 | E6: 0.1 | F6: 1.4 | G6: =SUM((E6*F6)*(240))/1000 -> 0.0336 | H6: =SUM((E6*F6)*(150))/1000 -> 0.021 | I6: =G6-H6 -> 0.0126
A7: 3 | B7: Bhagwanpura | C7: A | D7: 1 | E7: 0.06 | F7: 1.4 | G7: =SUM((E7*F7)*(240))/1000 -> 0.02016 | H7: =SUM((E7*F7)*(150))/1000 -> 0.0126 | I7: =G7-H7 -> 0.00756
A8: 4 | B8: Bhanwta | C8: A | D8: 1 | E8: 0.00625 | F8: 1.4 | G8: =SUM((E8*F8)*(240))/1000 -> 0.0021 | H8: =SUM((E8*F8)*(150))/1000 -> 0.0013125 | I8: =G8-H8 -> 0.0007875
A9: 5 | B9: Bhanwta | C9: A | D9: 1 | E9: 0.00625 | F9: 1.4 | G9: =SUM((E9*F9)*(240))/1000 -> 0.0021 | H9: =SUM((E9*F9)*(150))/1000 -> 0.0013125 | I9: =G9-H9 -> 0.0007875
A10: 6 | B10: Dantra | C10: A | D10: 1 | E10: 0.1 | F10: 1.4 | G10: =SUM((E10*F10)*(240))/1000 -> 0.0336 | H10: =SUM((E10*F10)*(150))/1000 -> 0.021 | I10: =G10-H10 -> 0.0126
A11: 7 | B11: Dev Nagar | C11: A | D11: 1 | E11: 0.00225 | F11: 1.4 | G11: =SUM((E11*F11)*(240))/1000 -> 0.000756 | H11: =SUM((E11*F11)*(150))/1000 -> 0.0004725 | I11: =G11-H11 -> 0.0002835
A12: 8 | B12: Dodiyana | C12: A | D12: 1 | E12: 0.09 | F12: 1.4 | G12: =SUM((E12*F12)*(240))/1000 -> 0.03024 | H12: =SUM((E12*F12)*(150))/1000 -> 0.0189 | I12: =G12-H12 -> 0.01134
A13: 9 | B13: Ganahera | C13: A | D13: 1 | E13: 0.11 | F13: 1.4 | G13: =SUM((E13*F13)*(240))/1000 -> 0.03696 | H13: =SUM((E13*F13)*(150))/1000 -> 0.0231 | I13: =G13-H13 -> 0.01386
A14: 10 | B14: Ganahera | C14: A | D14: 1 | E14: 0.1 | F14: 1.4 | G14: =SUM((E14*F14)*(240))/1000 -> 0.0336 | H14: =SUM((E14*F14)*(150))/1000 -> 0.021 | I14: =G14-H14 -> 0.0126
A15: 11 | B15: Govindgarh | C15: A | D15: 1 | E15: 0.11 | F15: 1.4 | G15: =SUM((E15*F15)*(240))/1000 -> 0.03696 | H15: =SUM((E15*F15)*(150))/1000 -> 0.0231 | I15: =G15-H15 -> 0.01386
A16: 12 | B16: Govindgarh | C16: A | D16: 1 | E16: 0.0006 | F16: 1.4 | G16: =SUM((E16*F16)*(240))/1000 -> 0.0002016 | H16: =SUM((E16*F16)*(150))/1000 -> 0.000126 | I16: =G16-H16 -> 7.56e-05
... A49: 45 | B49: Pushkar | C49: A | D49: 1 | E49: 1.575 | F49: 1.4 | G49: =SUM((E49*F49)*(240))/1000 -> 0.5292 | H49: =SUM((E49*F49)*(150))/1000 -> 0.33075 | I49: =G49-H49 -> 0.19845
D50: 1 | E50: =SUM(E5:E49) -> 4.38983 | F50: 1.4 | G50: =SUM((E50*F50)*(240))/1000 -> 1.4749829 | H50: =SUM((E50*F50)*(150))/1000 -> 0.9218643 | I50: =G50-H50 -> 0.55311858
A51: Source: Data as per the Village Base Line Survey of area of the village falls under aquifer boundary being conducted during March - April 2017 by CA Arpan Seva Sansthan under RACP

Sheet Dom Draft IV
A1: TABLE : IV - | C1: QUANTITATIVE ASSESSMENT OF ANNUAL PUMPAGE FROM EXISTING WELLS, TUBEWELLS AND HANDPUMPS IN USE FOR DRINKING PURPOSE IN ALLUVIUM POTENTIAL ZONES IN PEESANGAN GW CLUSTER, AJMER DISTRICT FOR THE YEAR 2016
A2: S. No. | B2: Village | C2: Zone | D2: Hydrogeological Formation | E2: Type of Well | F2: No. of Wells in use | G2: Average Discharge of Wells (LPD) | H2: No. of Operational Days | I2: Annual Withdrawl (mcm) | J2: Total Pumpage (mcm)
A3: 1 | B3: 2 | C3: 3 | D3: 4 | E3: 5 | F3: 6 | G3: 7 | H3: 8 | I3: 9 | J3: 10
A4: 1 | B4: Ambamassena | C4: A | D4: ALLUVIUM | E4: Tube well | F4: 0 | G4: 150000 | H4: 365 | I4: =F4*G4*H4/1000000000 -> 0 | J4: =SUM(I4:I6) -> 0.0438
E5: Dug cum Bore Well | F5: 1 | G5: 60000 | H5: 365 | I5: =F5*G5*H5/1000000000 -> 0.0219
E6: Dug well | F6: 4 | G6: 15000 | H6: 365 | I6: =F6*G6*H6/1000000000 -> 0.0219
A7: 2 | B7: Banseli | C7: A | D7: ALLUVIUM | E7: Tube well | F7: 1 | G7: 150000 | H7: 365 | I7: =F7*G7*H7/1000000000 -> 0.05475 | J7: =SUM(I7:I9) -> 0.1095
E8: Dug cum Bore Well | F8: 0 | G8: 60000 | H8: 365 | I8: =F8*G8*H8/1000000000 -> 0
E9: Dug well | F9: 10 | G9: 15000 | H9: 365 | I9: =F9*G9*H9/1000000000 -> 0.05475
A10: 3 | B10: Bhagwanpura | C10: A | D10: ALLUVIUM | E10: Tube well | F10: 2 | G10: 150000 | H10: 365 | I10: =F10*G10*H10/1000000000 -> 0.1095 | J10: =SUM(I10:I12) -> 0.14235
E11: Dug cum Bore Well | F11: 1 | G11: 60000 | H11: 365 | I11: =F11*G11*H11/1000000000 -> 0.0219
E12: Dug well | F12: 2 | G12: 15000 | H12: 365 | I12: =F12*G12*H12/1000000000 -> 0.01095
A13: 4 | B13: Bhanwta | C13: A | D13: ALLUVIUM | E13: Tube well | F13: 1 | G13: 150000 | H13: 365 | I13: =F13*G13*H13/1000000000 -> 0.05475 | J13: =SUM(I13:I15) -> 0.4599
E14: Dug cum Bore Well | F14: 0 | G14: 60000 | H14: 365 | I14: =F14*G14*H14/1000000000 -> 0
E15: Dug well | F15: 74 | G15: 15000 | H15: 365 | I15: =F15*G15*H15/1000000000 -> 0.40515
A16: 5 | B16: Budhwara | C16: A | D16: ALLUVIUM | E16: Tube well | F16: 5 | G16: 150000 | H16: 365 | I16: =F16*G16*H16/1000000000 -> 0.27375 | J16: =SUM(I16:I18) -> 0.3723
E17: Dug cum Bore Well | F17: 1 | G17: 60000 | H17: 365 | I17: =F17*G17*H17/1000000000 -> 0.0219
E18: Dug well | F18: 14 | G18: 15000 | H18: 365 | I18: =F18*G18*H18/1000000000 -> 0.07665
A19: 6 | B19: Chawandiya | C19: A | D19: ALLUVIUM | E19: Tube well | F19: 0 | G19: 150000 | H19: 365 | I19: =F19*G19*H19/1000000000 -> 0 | J19: =SUM(I19:I21) -> 0.093075
E20: Dug cum Bore Well | F20: 1 | G20: 60000 | H20: 365 | I20: =F20*G20*H20/1000000000 -> 0.0219
E21: Dug well | F21: 13 | G21: 15000 | H21: 365 | I21: =F21*G21*H21/1000000000 -> 0.071175
A22: 7 | B22: Dantra | C22: A | D22: ALLUVIUM | E22: Tube well | F22: 2 | G22: 150000 | H22: 365 | I22: =F22*G22*H22/1000000000 -> 0.1095 | J22: =SUM(I22:I24) -> 0.213525
E23: Dug cum Bore Well | F23: 1 | G23: 60000 | H23: 365 | I23: =F23*G23*H23/1000000000 -> 0.0219
E24: Dug well | F24: 15 | G24: 15000 | H24: 365 | I24: =F24*G24*H24/1000000000 -> 0.082125
A25: 8 | B25: Dev Nagar | C25: A | D25: ALLUVIUM | E25: Tube well | F25: 2 | G25: 150000 | H25: 365 | I25: =F25*G25*H25/1000000000 -> 0.1095 | J25: =SUM(I25:I27) -> 0.1095
E26: Dug cum Bore Well | F26: 0 | G26: 60000 | H26: 365 | I26: =F26*G26*H26/1000000000 -> 0
E27: Dug well | F27: 0 | G27: 15000 | H27: 365 | I27: =F27*G27*H27/1000000000 -> 0
A28: 9 | B28: Dodiyana | C28: A | D28: ALLUVIUM | E28: Tube well | F28: 1 | G28: 150000 | H28: 365 | I28: =F28*G28*H28/1000000000 -> 0.05475 | J28: =SUM(I28:I30) -> 0.0657
E29: Dug cum Bore Well | F29: 0 | G29: 60000 | H29: 365 | I29: =F29*G29*H29/1000000000 -> 0
E30: Dug well | F30: 2 | G30: 15000 | H30: 365 | I30: =F30*G30*H30/1000000000 -> 0.01095
A31: 10 | B31: Doomara | C31: A | D31: ALLUVIUM | E31: Tube well | F31: 1 | G31: 150000 | H31: 365 | I31: =F31*G31*H31/1000000000 -> 0.05475 | J31: =SUM(I31:I33) -> 0.12045
E32: Dug cum Bore Well | F32: 0 | G32: 60000 | H32: 365 | I32: =F32*G32*H32/1000000000 -> 0
E33: Dug well | F33: 12 | G33: 15000 | H33: 365 | I33: =F33*G33*H33/1000000000 -> 0.0657
A34: 11 | B34: Doongariya Khurd | C34: A | D34: ALLUVIUM | E34: Tube well | F34: 1 | G34: 150000 | H34: 365 | I34: =F34*G34*H34/1000000000 -> 0.05475 | J34: =SUM(I34:I36) -> 0.0657
E35: Dug cum Bore Well | F35: 0 | G35: 60000 | H35: 365 | I35: =F35*G35*H35/1000000000 -> 0
E36: Dug well | F36: 2 | G36: 15000 | H36: 365 | I36: =F36*G36*H36/1000000000 -> 0.01095
A37: 12 | B37: Fatehpura | C37: A | D37: ALLUVIUM | E37: Tube well | F37: 1 | G37: 150000 | H37: 365 | I37: =F37*G37*H37/1000000000 -> 0.05475 | J37: =SUM(I37:I39) -> 0.060225
E38: Dug cum Bore Well | F38: 0 | G38: 60000 | H38: 365 | I38: =F38*G38*H38/1000000000 -> 0
E39: Dug well | F39: 1 | G39: 15000 | H39: 365 | I39: =F39*G39*H39/1000000000 -> 0.005475
A40: 13 | B40: Ganahera | C40: A | D40: ALLUVIUM | E40: Tube well | F40: 8 | G40: 150000 | H40: 365 | I40: =F40*G40*H40/1000000000 -> 0.438 | J40: =SUM(I40:I42) -> 0.465375
...

Sheet Draft Irri-V
A1: TABLE-V : | C1: DRAFT FROM IRRIGATION WELLS SHOWING QUANTITATIVE ASSESSMENT OF ANNUAL PUMPAGE FROM EXISTING WELLS IN USE IN ALLUVIUM ZONES IN PEESANGAN GW CLUSTER OF AJMER DISTRICT FOR THE YEAR 2016
A2: S. No. | B2: Block | C2: Zone | D2: Hydrogeological Formation | F2: No. of Wells in use for irri | G2: Average Yield of Wells (m3/day) | H2: No. of Operational Days | I2: Annual Withdrawal (mcm) | J2: Total Draft (mcm)
A3: 1 | B3: 2 | C3: 3 | D3: 4 | E3: 5 | F3: 6 | G3: 7 | H3: 8 | I3: 9 | J3: 10
A4: 1 | B4: Ambamassena | C4: A | D4: ALLUVIUM | E4: Tube well | F4: 0 | G4: 150 | H4: 120 | I4: =F4*G4*H4/1000000 -> 0 | J4: =I4+I5+I6 -> 0.5952
E5: Dug cum Bore Well | F5: 1 | G5: 150 | H5: 120 | I5: =F5*G5*H5/1000000 -> 0.018
E6: Dug well | F6: 37 | G6: 130 | H6: 120 | I6: =F6*G6*H6/1000000 -> 0.5772
A7: 2 | B7: Banseli | C7: A | D7: ALLUVIUM | E7: Tube well | F7: 72 | G7: 150 | H7: 120 | I7: =F7*G7*H7/1000000 -> 1.296 | J7: =I7+I8+I9 -> 1.518
E8: Dug cum Bore Well | F8: 8 | G8: 150 | H8: 120 | I8: =F8*G8*H8/1000000 -> 0.144
E9: Dug well | F9: 5 | G9: 130 | H9: 120 | I9: =F9*G9*H9/1000000 -> 0.078
A10: 3 | B10: Bhagwanpura | C10: A | D10: ALLUVIUM | E10: Tube well | F10: 81 | G10: 150 | H10: 120 | I10: =F10*G10*H10/1000000 -> 1.458 | J10: =I10+I11+I12 -> 1.8972
E11: Dug cum Bore Well | F11: 14 | G11: 150 | H11: 120 | I11: =F11*G11*H11/1000000 -> 0.252
E12: Dug well | F12: 12 | G12: 130 | H12: 120 | I12: =F12*G12*H12/1000000 -> 0.1872
A13: 4 | B13: Bhanwta | C13: A | D13: ALLUVIUM | E13: Tube well | F13: 2 | G13: 150 | H13: 120 | I13: =F13*G13*H13/1000000 -> 0.036 | J13: =I13+I14+I15 -> 2.5368
E14: Dug cum Bore Well | F14: 2 | G14: 150 | H14: 120 | I14: =F14*G14*H14/1000000 -> 0.036
E15: Dug well | F15: 158 | G15: 130 | H15: 120 | I15: =F15*G15*H15/1000000 -> 2.4648
A16: 5 | B16: Budhwara | C16: A | D16: ALLUVIUM | E16: Tube well | F16: 42 | G16: 150 | H16: 120 | I16: =F16*G16*H16/1000000 -> 0.756 | J16: =I16+I17+I18 -> 2.2068
E17: Dug cum Bore Well | F17: 26 | G17: 150 | H17: 120 | I17: =F17*G17*H17/1000000 -> 0.468
E18: Dug well | F18: 63 | G18: 130 | H18: 120 | I18: =F18*G18*H18/1000000 -> 0.9828
A19: 6 | B19: Chawandiya | C19: A | D19: ALLUVIUM | E19: Tube well | F19: 21 | G19: 150 | H19: 120 | I19: =F19*G19*H19/1000000 -> 0.378 | J19: =I19+I20+I21 -> 0.5772
E20: Dug cum Bore Well | F20: 5 | G20: 150 | H20: 120 | I20: =F20*G20*H20/1000000 -> 0.09
E21: Dug well | F21: 7 | G21: 130 | H21: 120 | I21: =F21*G21*H21/1000000 -> 0.1092
A22: 7 | B22: Dantra | C22: A | D22: ALLUVIUM | E22: Tube well | F22: 17 | G22: 150 | H22: 120 | I22: =F22*G22*H22/1000000 -> 0.306 | J22: =I22+I23+I24 -> 2.262
E23: Dug cum Bore Well | F23: 9 | G23: 150 | H23: 120 | I23: =F23*G23*H23/1000000 -> 0.162
E24: Dug well | F24: 115 | G24: 130 | H24: 120 | I24: =F24*G24*H24/1000000 -> 1.794
A25: 8 | B25: Dev Nagar | C25: A | D25: ALLUVIUM | E25: Tube well | F25: 122 | G25: 150 | H25: 120 | I25: =F25*G25*H25/1000000 -> 2.196 | J25: =I25+I26+I27 -> 3.0144
E26: Dug cum Bore Well | F26: 42 | G26: 150 | H26: 120 | I26: =F26*G26*H26/1000000 -> 0.756
E27: Dug well | F27: 4 | G27: 130 | H27: 120 | I27: =F27*G27*H27/1000000 -> 0.0624
A28: 9 | B28: Dodiyana | C28: A | D28: ALLUVIUM | E28: Tube well | F28: 0 | G28: 150 | H28: 120 | I28: =F28*G28*H28/1000000 -> 0 | J28: =I28+I29+I30 -> 0.2856
E29: Dug cum Bore Well | F29: 2 | G29: 150 | H29: 120 | I29: =F29*G29*H29/1000000 -> 0.036
E30: Dug well | F30: 16 | G30: 130 | H30: 120 | I30: =F30*G30*H30/1000000 -> 0.2496
A31: 10 | B31: Doomara | C31: A | D31: ALLUVIUM | E31: Tube well | F31: 2 | G31: 150 | H31: 120 | I31: =F31*G31*H31/1000000 -> 0.036 | J31: =I31+I32+I33 -> 0.8472
E32: Dug cum Bore Well | F32: 0 | G32: 150 | H32: 120 | I32: =F32*G32*H32/1000000 -> 0
E33: Dug well | F33: 52 | G33: 130 | H33: 120 | I33: =F33*G33*H33/1000000 -> 0.8112
A34: 11 | B34: Doongariya Khurd | C34: A | D34: ALLUVIUM | E34: Tube well | F34: 11 | G34: 150 | H34: 120 | I34: =F34*G34*H34/1000000 -> 0.198 | J34: =I34+I35+I36 -> 0.2316
E35: Dug cum Bore Well | F35: 1 | G35: 150 | H35: 120 | I35: =F35*G35*H35/1000000 -> 0.018
E36: Dug well | F36: 1 | G36: 130 | H36: 120 | I36: =F36*G36*H36/1000000 -> 0.0156
A37: 12 | B37: Fatehpura | C37: A | D37: ALLUVIUM | E37: Tube well | F37: 3 | G37: 150 | H37: 120 | I37: =F37*G37*H37/1000000 -> 0.054 | J37: =I37+I38+I39 -> 0.2412
E38: Dug cum Bore Well | F38: 0 | G38: 150 | H38: 120 | I38: =F38*G38*H38/1000000 -> 0
E39: Dug well | F39: 12 | G39: 130 | H39: 120 | I39: =F39*G39*H39/1000000 -> 0.1872
A40: 13 | B40: Ganahera | C40: A | D40: ALLUVIUM | E40: Tube well | F40: 147 | G40: 150 | H40: 120 | I40: =F40*G40*H40/1000000 -> 2.646 | J40: =I40+I41+I42 -> 2.9808
...

Sheet Draft Irr.Area
A1: TABLE-VI : DRAFT BASED ON IRRIGATED AREA & ITS AVERAGE WATER REQUIREMENT OF CROPS
A3: S. No. | B3: Block | C3: Potential Zone | D3: Hydrogeological Formation | E3: Area Irrigation (Sq.Km.) | F3: Depth of Watering (Sq.Km.) | G3: Water Requirement (mcm)
A4: 1 | B4: Ambamassena | C4: A | D4: ALLUVIUM | E4: ='APP 2015-16'!#REF! -> #REF! | F4: 0.55 | G4: =ROUND(E4*F4,4) -> #REF!
A5: 2 | B5: Banseli | C5: A | D5: ALLUVIUM | E5: ='APP 2015-16'!#REF! -> #REF! | F5: 0.55 | G5: =ROUND(E5*F5,4) -> #REF!
A6: 3 | B6: Bhagwanpura | C6: A | D6: ALLUVIUM | E6: 1.6101268 | F6: 0.55 | G6: =ROUND(E6*F6,4) -> 0.8856
A7: 4 | B7: Bhanwta | C7: A | D7: ALLUVIUM | E7: 5.2044874 | F7: 0.55 | G7: =ROUND(E7*F7,4) -> 2.8625
A8: 5 | B8: Budhwara | C8: A | D8: ALLUVIUM | E8: 7.3500705 | F8: 0.55 | G8: =ROUND(E8*F8,4) -> 4.0425
A9: 6 | B9: Chawandiya | C9: A | D9: ALLUVIUM | E9: 0.49749005 | F9: 0.55 | G9: =ROUND(E9*F9,4) -> 0.2736
A10: 7 | B10: Dantra | C10: A | D10: ALLUVIUM | E10: 6.9175916 | F10: 0.55 | G10: =ROUND(E10*F10,4) -> 3.8047
A11: 8 | B11: Dev Nagar | C11: A | D11: ALLUVIUM | E11: 0.754467 | F11: 0.55 | G11: =ROUND(E11*F11,4) -> 0.415
A12: 9 | B12: Dodiyana | C12: A | D12: ALLUVIUM | E12: 1.2677038 | F12: 0.55 | G12: =ROUND(E12*F12,4) -> 0.6972
A13: 10 | B13: Doomara | C13: A | D13: ALLUVIUM | E13: 0.90004573 | F13: 0.55 | G13: =ROUND(E13*F13,4) -> 0.495
A14: 11 | B14: Doongariya Khurd | C14: A | D14: ALLUVIUM | E14: 0.1338866 | F14: 0.55 | G14: =ROUND(E14*F14,4) -> 0.0736
A15: 12 | B15: Fatehpura | C15: A | D15: ALLUVIUM | E15: 0.23661541 | F15: 0.55 | G15: =ROUND(E15*F15,4) -> 0.1301
A16: 13 | B16: Ganahera | C16: A | D16: ALLUVIUM | E16: 0.46088567 | F16: 0.55 | G16: =ROUND(E16*F16,4) -> 0.2535
A17: 14 | B17: Govindgarh | C17: A | D17: ALLUVIUM | E17: 2.4605115 | F17: 0.55 | G17: =ROUND(E17*F17,4) -> 1.3533
... A47: 44 | B47: Tilora | C47: A | D47: ALLUVIUM | E47: 0.36119231 | F47: 0.55 | G47: =ROUND(E47*F47,4) -> 0.1987
E48: =SUM(E4:E47) -> #REF! | F48: 0.55 | G48: =ROUND(E48*F48,4) -> #REF!
A49: Source: Data as per the Agriculture data receive from the DPM, Agriculture Department, Ajmer From: dy director <ddagr_ajm@rediffmail.com> Dated: Fri, Aug 25, 2017 at 12:17 PM through e mail

Sheet Draft Depl
A1: TABLE - VII : DRAFT BASED ON DEPLETION OF WATER LEVEL BETWEEN POST MONSOON 2016 & PRE-MONSOON 2017
A3: S. No. | B3: Village | C3: Potential Zone | D3: Hydrogeological Formation | E3: Area (Sq.Km.) | F3: Specific Yield (%) | G3: Depletion (m) Post 2016 - Pre-2017 | H3: Draft based on Depletion (mcm)
A4: 1 | B4: 2 | C4: 3 | D4: 4 | E4: 5 | F4: 6 | G4: 7 | H4: 8
A5: 1 | B5: Ambamassena | C5: A | D5: ALLUVIUM | E5: 5.71 | F5: 12 | G5: 2.1 | H5: =ROUND(E5*F5*G5/100,4) -> 1.4389
A6: 2 | B6: Banseli | C6: A | D6: ALLUVIUM | E6: 4.11 | F6: 12 | G6: 0.22 | H6: =ROUND(E6*F6*G6/100,4) -> 0.1085
A7: 3 | B7: Bhagwanpura | C7: A | D7: ALLUVIUM | E7: 9.56 | F7: 12
A8: 4 | B8: Bhanwta | C8: A | D8: ALLUVIUM | E8: 10.68 | F8: 12 | G8: 1.98 | H8: =ROUND(E8*F8*G8/100,4) -> 2.5376
A9: 5 | B9: Budhwara | C9: A | D9: ALLUVIUM | E9: 21.01 | F9: 12 | G9: 1.61 | H9: =ROUND(E9*F9*G9/100,4) -> 4.0591
A10: 6 | B10: Chawandiya | C10: A | D10: ALLUVIUM | E10: 4.29 | F10: 12 | H10: =ROUND(E10*F10*G10/100,4) -> 0
A11: 7 | B11: Dantra | C11: A | D11: ALLUVIUM | E11: 12.1 | F11: 12 | G11: 1.69 | H11: =ROUND(E11*F11*G11/100,4) -> 2.4539
A12: 8 | B12: Dev Nagar | C12: A | D12: ALLUVIUM | E12: 5.99 | F12: 12 | G12: 0.5 | H12: =ROUND(E12*F12*G12/100,4) -> 0.3594
A13: 9 | B13: Dodiyana | C13: A | D13: ALLUVIUM | E13: 9.15 | F13: 12 | G13: 1.37 | H13: =ROUND(E13*F13*G13/100,4) -> 1.5043
A14: 10 | B14: Doomara | C14: A | D14: ALLUVIUM | E14: 2.41 | F14: 12 | G14: 2.08 | H14: =ROUND(E14*F14*G14/100,4) -> 0.6015
A15: 11 | B15: Doongariya Khurd | C15: A | D15: ALLUVIUM | E15: 4.32 | F15: 12 | G15: 1.5 | H15: =ROUND(E15*F15*G15/100,4) -> 0.7776
A16: 12 | B16: Fatehpura | C16: A | D16: ALLUVIUM | E16: 1.9 | F16: 12 | G16: 1.5 | H16: =ROUND(E16*F16*G16/100,4) -> 0.342
A17: 13 | B17: Ganahera | C17: A | D17: ALLUVIUM | E17: 5.95 | F17: 12 | G17: 2.18 | H17: =ROUND(E17*F17*G17/100,4) -> 1.5565
A18: 14 | B18: Govindgarh | C18: A | D18: ALLUVIUM | E18: 6.38 | F18: 12 | G18: 1.89 | H18: =ROUND(E18*F18*G18/100,4) -> 1.447
A19: 15 | B19: Gudha | C19: A | D19: ALLUVIUM | E19: 2.9 | F19: 12 | H19: =ROUND(E19*F19*G19/100,4) -> 0
A20: 16 | B20: Hanwantpura | C20: A | D20: ALLUVIUM | E20: 1.41 | F20: 12 | G20: 1.95 | H20: =ROUND(E20*F20*G20/100,4) -> 0.3299
A21: 17 | B21: Jaswantpura | C21: A | D21: ALLUVIUM | E21: 15.71 | F21: 12 | H21: =ROUND(E21*F21*G21/100,4) -> 0
A22: 18 | B22: Kalesara | C22: A | D22: ALLUVIUM | E22: 19.83 | F22: 12 | G22: 2.25 | H22: =ROUND(E22*F22*G22/100,4) -> 5.3541
A23: 19 | B23: Kawlai | C23: A | D23: ALLUVIUM | E23: 2.34 | F23: 12 | G23: 0.91 | H23: =ROUND(E23*F23*G23/100,4) -> 0.2555
A24: 20 | B24: Khori | C24: A | D24: ALLUVIUM | E24: 3.19 | F24: 12 | G24: 1.03 | H24: =ROUND(E24*F24*G24/100,4) -> 0.3943
A25: 21 | B25: Kishanpura Goyla | C25: A | D25: ALLUVIUM | E25: 11.91 | F25: 12 | G25: 0.74 | H25: =ROUND(E25*F25*G25/100,4) -> 1.0576
A26: 22 | B26: Leswa | C26: A | D26: ALLUVIUM | E26: 13.36 | F26: 12 | G26: 1.15 | H26: =ROUND(E26*F26*G26/100,4) -> 1.8437
A27: 23 | B27: Laylikhera | C27: A | D27: ALLUVIUM | E27: 4.67 | F27: 12 | G27: 0.85 | H27: =ROUND(E27*F27*G27/100,4) -> 0.4763
A28: 24 | B28: Kadel | C28: A | D28: ALLUVIUM | E28: 1.11 | F28: 12 | G28: 2.96 | H28: =ROUND(E28*F28*G28/100,4) -> 0.3943
A29: 25 | B29: Majhewla | C29: A | D29: ALLUVIUM | E29: 3.21 | F29: 12 | H29: =ROUND(E29*F29*G29/100,4) -> 0
A30: 26 | B30: Miyapur | C30: A | D30: ALLUVIUM | E30: 2.03 | F30: 12 | H30: =ROUND(E30*F30*G30/100,4) -> 0
A31: 27 | B31: Motisar | C31: A | D31: ALLUVIUM | E31: 3.31 | F31: 12 | H31: =ROUND(E31*F31*G31/100,4) -> 0
A32: 28 | B32: Nad | C32: A | D32: ALLUVIUM | E32: 9.21 | F32: 12 | H32: =ROUND(E32*F32*G32/100,4) -> 0
A33: 29 | B33: Nand | C33: A | D33: ALLUVIUM | E33: 13.93 | F33: 12 | H33: =ROUND(E33*F33*G33/100,4) -> 0
A34: 30 | B34: Nathuthala | C34: A | D34: ALLUVIUM | E34: 4.38 | F34: 12 | G34: 1.08 | H34: =ROUND(E34*F34*G34/100,4) -> 0.5676
A35: 31 | B35: Nooriyawas | C35: A | D35: ALLUVIUM | E35: 6.08 | F35: 12 | G35: 1.97 | H35: =ROUND(E35*F35*G35/100,4) -> 1.4373
A36: 32 | B36: Picholiya | C36: A | D36: ALLUVIUM | E36: 16.8 | F36: 12 | H36: =ROUND(E36*F36*G36/100,4) -> 0
A37: 33 | B37: Pisangan | C37: A | D37: ALLUVIUM | E37: 20.25 | F37: 12 | G37: 2.09 | H37: =ROUND(E37*F37*G37/100,4) -> 5.0787
A38: 34 | B38: Pushkar (M) | C38: A | D38: ALLUVIUM | E38: 2.16 | F38: 12 | G38: 1.95 | H38: =ROUND(E38*F38*G38/100,4) -> 0.5054
A39: 35 | B39: Pushkar (R) | C39: A | D39: ALLUVIUM | E39: 2.19 | F39: 12 | H39: =ROUND(E39*F39*G39/100,4) -> 0
A40: 36 | B40: Rampura Dabla | C40: A | D40: ALLUVIUM | E40: 10.67 | F40: 12 | G40: 1.78 | H40: =ROUND(E40*F40*G40/100,4) -> 2.2791
A41: 37 | B41: Rampura Nand | C41: A | D41: ALLUVIUM | E41: 3.52 | F41: 12 | H41: =ROUND(E41*F41*G41/100,4) -> 0
...

Sheet Sheet1

Sheet Compar
A2: TABLE-VII:-COMPARISION OF EXTRACTION OF GROUD WATER BY DIFFERENT METHODS AND
A3: ACCEPTED VALUE OF IRRIGATION DRAFT IN PEESANGAN GW CLUSTER
A5: S.No. | B5: Block | C5: Potential Zone | D5: Area of Potential Zone (Sq.Km.) | E5: Average Water Levels (m) | G5: Depl-etion (m) | H5: Specific Yield | I5: Decrease in Storage (mcm) | J5: Water Requirement by Different crops (mcm) | N5: Extraction of Water through wells (mcm) | Q5: Accepted Value of Draft for Irrigation (mcm)
E6: Post 16 | F6: Pre 17 | J6: Rabi | K6: Kharif | L6: Zaid | M6: Gross | N6: Irrigation | O6: Domestic | P6: Gross
A8: 1 | B8: Peesangan | C8: Ao | D8: ='ASS June2017'!BA8 -> 318.25 | E8: ='WaterLevel 12-16'!T88 -> 20.2 | F8: ='WaterLevel 12-16'!V88 -> 21.571867 | G8: 1.37 | H8: 0.12 | I8: =(D8*G8*H8) -> 52.3203 | J8: ='Crop Water'!F19 -> 46.68166 | K8: ='Crop Water'!F11 -> 5.666187 | L8: ='Crop Water'!F24 -> 1.1596422 | M8: =SUM(J8:L8) -> 53.507489 | N8: ='Draft Irri-V'!J136 -> 41.5308 | O8: ='Dom Draft IV'!J136 -> 6.356475 | P8: =(N8+O8) -> 47.887275 | Q8: =M8 -> 53.507489

Sheet Reccomendation
J1: TABLE-XVII
A2: BLOCKWISE AND ZONEWISE RECOMMENDATIONS FOR FUTURE
A3: GROUND WATER DEVELOPMENT IN IN PEESANGAN GW CLUSTER AJMER DISTRICT
A4: Block | B4: Area of | C4: Type of | D4: Potential | E4: Potential | F4: Expected Water Level (m) | G4: Recommendations | K4: Stage of Ground Water Development %
B5: Block | C5: Area | D5: zone | E5: zone | G5: Type of Well | H5: Dia of well | I5: Depth of | J5: Expected
B6: Sq.Km. | E6: area | H6: Tubewell-mm | I6: well | J6: Yield
E7: sq.km. | H7: Dugwell-m | I7: (m) | J7: (m3/day)
A8: PEESANGAN | B8: 318.25 | C8: Non Command | D8: Ao | E8: =B8-G18 -> 299.02 | G8: Not recommended for future ground water development | K8: ='ASS June2017'!BH8 -> 237.63
D9: Block | G9: Not recommended for future ground water development | K9: =K8 -> 237.63
F13: Total area | G13: 318.25
E14: Non potential | F14: Barren rockey | G14: 1.07 | H14: =G14/G13% -> 0.33621367
F15: Salt affected | G15: 4.98 | H15: =G15/G13% -> 1.5648075
F16: Gullied & revined | G16: 5.8 | H16: =G16/G13% -> 1.8224666
F17: Built up | G17: 7.38 | H17: =G17/G13% -> 2.3189317
G18: =SUM(G14:G17) -> 19.23 | H18: =G18/G13% -> 6.0424195
F19: Potential zone area | G19: =G13-G18 -> 299.02 | H19: =G19/G13% -> 93.957581

Sheet WaterLevel trend
A1: WATER LEVEL FLUCTUATION DATA (MTS) FROM 2007-2016 OF Peesangan GW cluster area
A2: S.NO | B2: NAME OF VILLAGE | C2: OWNER NAME | D2: ='[1]wl2006-2011'!F1:F2 -> Longitude | F2: TOTAL DEPTH | G2: 2007 | H2: 2008 | I2: 2009 | J2: 2010 | K2: 2011 | L2: 2012 | M2: 2013 | N2: 2014 | O2: 2015 | P2: 2016 | R2: 2007 | S2: 2008 | T2: 2009 | U2: 2010 | V2: 2011 | W2: 2012 | X2: 2013 | Y2: 2014 | Z2: 2015 | AA2: 2016
D3: Longitude | E3: Latitude | G3: PRE | H3: PRE | I3: PRE | J3: PRE | K3: PRE | L3: PRE | M3: PRE | N3: PRE | O3: PRE | P3: PRE | R3: POST | S3: POST | T3: POST | U3: POST | V3: POST | W3: POST | X3: POST | Y3: POST | Z3: POST | AA3: POST
A4: 1 | B4: Bhanwta | C4: PRAHLAD PATWARI | D4: 26°26'46.77'' | E4: 74°27'54.73'' | F4: 23 | G4: 18.68 | H4: 24.55 | I4: 26.46 | J4: 29.3 | K4: 20.17 | L4: 20.42 | M4: 16.95 | N4: 17.25 | O4: 19.02 | P4: 19.1 | R4: 18.5 | S4: 24.45 | T4: 27.65 | U4: 30.35 | V4: 16.48 | W4: 16.25 | X4: 17.13 | Y4: 16.25 | Z4: 18.05 | AA4: 17.1
A5: 2 | B5: Leswa | C5: G.W.D. | D5: 26°28'19.13'' | E5: 74°25'33.58'' | F5: 80 | G5: 23.45 | H5: 24.95 | I5: 25.9 | J5: 29.45 | K5: 32.55 | L5: 35.47 | M5: 36.9 | N5: 38.13 | O5: 40.13 | P5: 43.25 | R5: 22.25 | S5: 24.14 | T5: 26.45 | U5: 28.95 | V5: 32.35 | W5: 36.1 | X5: 36.85 | Y5: 37.1 | Z5: 39.6 | AA5: 42.1
A6: 3 | B6: Govindgarh | C6: LAXMAN NATHU YADAV | D6: 26°13'54.69'' | E6: 74°23'38.1'' | F6: 26.15 | G6: 19.25 | H6: 19.35 | I6: 20.23 | J6: 19.2 | K6: 18.74 | L6: 18.27 | M6: 18.15 | N6: 18.7 | O6: 19.1 | P6: 18.4 | R6: 18.4 | S6: 18.92 | T6: 21.05 | U6: 18.8 | V6: 18.49 | W6: 17.62 | X6: 17.8 | Y6: 17.5 | Z6: 18.7 | AA6: 19.2
A7: 4 | B7: PEESANGAN | C7: G.W.D. | D7: 26°21'22.35'' | E7: 74°22'51.85'' | F7: 30 | G7: 17.3 | H7: 22.4 | I7: 23.49 | J7: 23.65 | K7: 17.42 | L7: 18.85 | M7: 17.46 | N7: 19.26 | O7: 19.9 | P7: 21.8 | R7: 15.65 | S7: 19.68 | T7: 23.7 | U7: 12.5 | V7: 16.6 | W7: 13.16 | X7: 17.95 | Y7: 17.9 | Z7: 17.74 | AA7: 20.9
A8: 5 | B8: Saradhana | C8: SWAJ KARAN KAJJA CHANGAL (JAT) | D8: 26°24'55.65'' | E8: 74°18'44.43'' | F8: 36.5 | G8: 19.5 | H8: 32.45 | I8: 34.1 | J8: 34.42 | K8: 35.86 | L8: 26.65 | M8: 23.25 | N8: 23.86 | O8: 23.86 | P8: 25.4 | R8: 16.65 | S8: 31.72 | T8: 35.02 | U8: 36.26 | V8: 23.35 | W8: 22.5 | X8: 22.9 | Y8: 20.6 | Z8: 20.6 | AA8: 23.36
A9: 6 | B9: Sarsari | C9: Ranjeet Ji Jat | D9: 26°21'9.44'' | E9: 74°35'18.66'' | F9: 37.5 | G9: 13.3 | H9: 11.45 | I9: 18.8 | J9: 21 | K9: 15.88 | L9: 17.1 | M9: 16.5 | N9: 18.8 | O9: 17.95 | P9: 18.8 | R9: 14.2 | S9: 5.04 | T9: 20.9 | U9: 13.28 | V9: 8.4 | W9: 9.85 | X9: 16.9 | Y9: 16.35 | Z9: 17.25 | AA9: 16.7
A10: 7 | B10: NALA PUSHKER | C10: RATHANA JI S/O DALAJI 9828939651 | D10: 26.485025 | E10: 74.56454 | F10: 32.4 | G10: 19.6 | H10: 29.5 | I10: 29.1 | J10: 29.46 | K10: 29.36 | L10: 29 | M10: 28.79 | N10: 29.36 | O10: 29.36 | P10: 28.8 | R10: 14.5 | S10: 24.12 | T10: 29.4 | U10: 29.51 | V10: 29.26 | W10: 28.75 | X10: 27.78 | Y10: 28.1 | Z10: 29.1 | AA10: 25.95
A11: 8 | B11: KAWALAI | C11: CHODUSINGH S/O UMA SINGH | D11: 26.594715 | E11: 74.592616 | F11: 35.5 | G11: 18.45 | H11: 31 | I11: 30.85 | J11: 31.5 | K11: 31.97 | L11: 32.37 | M11: 32.45 | N11: 32.8 | O11: 34.95 | P11: 34.1 | R11: 17.95 | S11: 28.47 | T11: 31.45 | U11: 30.14 | V11: 31.95 | W11: 31.35 | X11: 31.9 | Y11: 31.15 | Z11: 33.1 | AA11: 32.4
B12: Average | G12: =AVERAGE(G4:G11) -> 18.69125 | H12: =AVERAGE(H4:H11) -> 24.45625 | I12: =AVERAGE(I4:I11) -> 26.11625 | J12: =AVERAGE(J4:J11) -> 27.2475 | K12: =AVERAGE(K4:K11) -> 25.24375 | L12: =AVERAGE(L4:L11) -> 24.76625 | M12: =AVERAGE(M4:M11) -> 23.80625 | N12: =AVERAGE(N4:N11) -> 24.77 | ... P12: =AVERAGE(P4:P11) -> 26.20625 | R12: =AVERAGE(R4:R11) -> 17.2625 | S12: =AVERAGE(S4:S11) -> 22.0675 | T12: =AVERAGE(T4:T11) -> 26.9525 | U12: =AVERAGE(U4:U11) -> 24.97375 | V12: =AVERAGE(V4:V11) -> 22.11 | W12: =AVERAGE(W4:W11) -> 21.9475 | X12: =AVERAGE(X4:X11) -> 23.65125 | Y12: =AVERAGE(Y4:Y11) -> 23.11875 | ... AA12: =AVERAGE(AA4:AA11) -> 24.71375

Sheet WaterLevel 12-16
A1: WATER LEVEL FLUCTUATION DATA (MTS) FROM 2007-2016 OF Peesangan GW cluster area
A2: S.NO | B2: NAME OF VILLAGE | C2: OWNER NAME | D2: ='[1]wl2006-2011'!F1:F2 -> Longitude | F2: TOTAL DEPTH | G2: 2012 | J2: 2013 | M2: 2014 | P2: 2015 | S2: 2016 | V2: 2017 | W2: Post 16 - Pre 17
D3: Longitude | E3: Latitude | G3: PRE | H3: POST | I3: FLU | J3: PRE | K3: POST | L3: FLU | M3: PRE | N3: POST | O3: FLU | P3: PRE | Q3: POST | R3: FLU | S3: PRE | T3: POST | U3: FLU | V3: Pre | W3: FLU
A4: 1 | B4: Bhagwanpura | C4: G.W.D. | D4: 26°26'56.52'' | E4: 74°27'55.2'' | F4: 30.5 | G4: 25.7 | H4: 22.17 | I4: =G4-H4 -> 3.53 | J4: 25.5 | K4: 25.3 | L4: =J4-K4 -> 0.2 | M4: 28 | N4: 26.9 | O4: =M4-N4 -> 1.1 | P4: 28.5 | Q4: 27.9 | R4: =P4-Q4 -> 0.6 | S4: 29.75 | T4: 28.9 | U4: =S4-T4 -> 0.85 | Y4: 3.15 | Z4: =T4+Y4 -> 32.05
A5: 2 | B5: Bhanwta | C5: PRAHLAD PATWARI | D5: 26°26'46.77'' | E5: 74°27'54.73'' | F5: 23 | G5: 12.95 | H5: 8.4 | I5: =G5-H5 -> 4.55 | J5: 16.95 | K5: 17.13 | L5: =J5-K5 -> -0.18 | M5: 17.25 | N5: 16.25 | O5: =M5-N5 -> 1 | P5: 19.02 | Q5: 18.05 | R5: =P5-Q5 -> 0.97 | S5: 19.1 | T5: 17.1 | U5: =S5-T5 -> 2 | V5: 20.1 | W5: =V5-T5 -> 3
A6: 3 | B6: Budhwara | C6: CHATARBHUJ S/O BARDAJI | D6: 26°16'8.64'' | E6: 74°37'22.35'' | F6: 35 | G6: 30.3 | H6: 23.48 | I6: 1.95 | J6: 30.3 | K6: 29.34 | L6: =J6-K6 -> 0.96 | M6: 31.47 | N6: 29.95 | O6: =M6-N6 -> 1.52 | P6: 32.01 | Q6: 30.15 | R6: =P6-Q6 -> 1.86 | S6: - | T6: dry
A7: 4 | B7: Ganahera | C7: G.W.D. | D7: 26°22'22'' | E7: 74°26'7.55'' | F7: 30 | G7: 27.8 | H7: 27.45 | I7: =G7-H7 -> 0.35 | J7: 27.8 | K7: 27.5 | L7: =J7-K7 -> 0.3 | M7: 29.13 | N7: 27.5 | O7: =M7-N7 -> 1.63 | P7: 31.75 | Q7: 32.15 | R7: =P7-Q7 -> -0.4 | S7: - | T7: dry
A8: 5 | B8: Leswa | C8: G.W.D. | D8: 26°28'19.13'' | E8: 74°25'33.58'' | F8: 80 | G8: 39.26 | H8: 31.48 | I8: =G8-H8 -> 7.78 | J8: 36.9 | K8: 36.85 | L8: =J8-K8 -> 0.05 | M8: 38.13 | N8: 37.1 | O8: =M8-N8 -> 1.03 | P8: 40.13 | Q8: 39.6 | R8: =P8-Q8 -> 0.53 | S8: 43.25 | T8: 42.1 | U8: =S8-T8 -> 1.15 | V8: 44.1 | W8: =V8-T8 -> 2
A9: 6 | B9: Pushkar (Rural) | C9: G.W.D. | D9: 26°24'27.43'' | E9: 74°28'10.24'' | F9: 21.3 | G9: 29 | H9: 28.75 | I9: =G9-H9 -> 0.25 | J9: 28.79 | K9: 28.78 | L9: =J9-K9 -> 0.01 | M9: 29.36 | N9: 28.1 | O9: =M9-N9 -> 1.26 | P9: 30.36 | Q9: 28.9 | R9: =P9-Q9 -> 1.46 | S9: 29.2 | T9: 29.1 | U9: =S9-T9 -> 0.1
A10: 7 | B10: Kawalai | C10: NANU RAM HAMIRA RAWAT | D10: 26°17'23.3'' | E10: 74°17'18.34'' | F10: 33.5 | G10: 32.45 | H10: 31.1 | I10: =G10-H10 -> 1.35 | J10: 29.75 | K10: 29.7 | L10: =J10-K10 -> 0.05 | M10: 31.7 | N10: 29.35 | O10: =M10-N10 -> 2.35 | P10: 32.7 | Q10: 29.35 | R10: =P10-Q10 -> 3.35 | S10: 33.6 | T10: 32.9 | U10: =S10-T10 -> 0.7 | V10: 33.53 | W10: =V10-T10 -> 0.63
A11: 8 | B11: Govindgarh | C11: LAXMAN NATHU YADAV | D11: 26°13'54.69'' | E11: 74°23'38.1'' | F11: 26.15 | G11: 18.15 | H11: 17.62 | I11: =G11-H11 -> 0.53 | J11: 18.15 | K11: 17.8 | L11: =J11-K11 -> 0.35 | M11: 18.7 | N11: 17.5 | O11: =M11-N11 -> 1.2 | P11: 19.1 | Q11: 18.7 | R11: =P11-Q11 -> 0.4 | S11: 18.4 | T11: 19.2 | U11: =S11-T11 -> -0.8 | V11: 19.5 | W11: =V11-T11 -> 0.3
A12: 9 | B12: Nad | C12: RAMJI S/O KASTUR JI | D12: 26°28'2.69'' | E12: 74°30'30'' | F12: 21 | G12: 7.02 | H12: 6.82 | I12: =G12-H12 -> 0.2 | J12: 11.25 | K12: 11.4 | L12: =J12-K12 -> -0.15 | M12: 12.1 | N12: 10.7 | O12: =M12-N12 -> 1.4 | P12: 13.25 | Q12: 12.7 | R12: =P12-Q12 -> 0.55 | S12: 17.9 | T12: 17.65 | U12: =S12-T12 -> 0.25
A13: 10 | B13: PEESANGAN | C13: G.W.D. | D13: 26°21'22.35'' | E13: 74°22'51.85'' | F13: 30 | G13: 20.46 | H13: 17.18 | I13: =G13-H13 -> 3.28 | J13: 17.46 | K13: 17.95 | L13: =J13-K13 -> -0.49 | M13: 19.26 | N13: 17.9 | O13: =M13-N13 -> 1.36 | P13: 19.9 | Q13: 17.74 | R13: =P13-Q13 -> 2.16 | S13: 21.8 | T13: 20.9 | U13: =S13-T13 -> 0.9 | V13: 23.2 | W13: =V13-T13 -> 2.3
A14: 11 | B14: PEESANGAN | C14: NAURATMAL SONI | D14: 26°24'3.97'' | E14: 74°22'52.47'' | F14: 25 | G14: 13.15 | H14: 7.78 | I14: =G14-H14 -> 5.37 | J14: 15.15 | K14: 15.88 | L14: =J14-K14 -> -0.73 | M14: 18.6 | N14: 17.6 | O14: =M14-N14 -> 1 | P14: 18.6 | Q14: 20.1 | R14: =P14-Q14 -> -1.5 | S14: 23.1 | T14: 24.14 | U14: =S14-T14 -> -1.04 | V14: 25.4 | W14: =V14-T14 -> 1.26
A15: 12 | B15: Saradhana | C15: SWAJ KARAN KAJJA CHANGAL (JAT) | D15: 26°24'55.65'' | E15: 74°18'44.43'' | F15: 36.5 | G15: 26.65 | H15: 22.5 | I15: =G15-H15 -> 4.15 | J15: 23.25 | K15: 22.9 | L15: =J15-K15 -> 0.35 | M15: 23.86 | N15: 20.6 | O15: =M15-N15 -> 3.26 | P15: 23.86 | Q15: 20.6 | R15: =P15-Q15 -> 3.26 | S15: 25.4 | T15: 23.36 | U15: =S15-T15 -> 2.04
A16: 13 | B16: Kalesara | C16: Jameel Chhipa | D16: 26°20'7.5'' | E16: 74°19'21.46'' | F16: 27 | G16: 5.25 | H16: 4.47 | I16: 0.78 | J16: 15.25 | K16: 15.2 | L16: =J16-K16 -> 0.05 | M16: 17.9 | N16: 17.1 | O16: =M16-N16 -> 0.8 | P16: 15.9 | Q16: 12.3 | R16: =P16-Q16 -> 3.6 | S16: 13 | T16: 12.7 | U16: =S16-T16 -> 0.3
A17: 14 | B17: Sarsari | C17: Ranjeet Ji Jat | D17: 26°21'9.44'' | E17: 74°35'18.66'' | F17: 37.5 | G17: 10.5 | H17: 10.4 | I17: =G17-H17 -> 0.1 | J17: 16.5 | K17: 16.9 | L17: =J17-K17 -> -0.4 | M17: 18.8 | N17: 16.35 | O17: =M17-N17 -> 2.45 | P17: 17.95 | Q17: 17.25 | R17: =P17-Q17 -> 0.7 | S17: 18.8 | T17: 16.7 | U17: =S17-T17 -> 2.1 | V17: 18.55 | W17: =V17-T17 -> 1.85
A18: 15 | B18: AMBAMASEENA | C18: Sh.Panchu singh ji /deva ji | D18: 26 22 21.1 | E18: 74 32 26.4 | F18: 30 | P18: 3.95 | Q18: 4.3 | R18: =P18-Q18 -> -0.35 | S18: 6.3 | T18: 3.55 | U18: =S18-T18 -> 2.75 | V18: 4.7 | W18: =V18-T18 -> 1.15
A19: 17 | B19: Budhwara | C19: Shri Harkaran Ji/Balu ji Jat | D19: 26 21 50.5 | E19: 74 26 47.7 | F19: 40 | P19: 14.84 | Q19: 16 | R19: =P19-Q19 -> -1.16 | S19: 30.6 | T19: 28.25 | U19: =S19-T19 -> 2.35 | V19: 30.21 | W19: =V19-T19 -> 1.96
A20: 18 | B20: Dodiyana | C20: Shri Babulal Ji /Heeralal ji Mali | D20: 26 20 00.0 | E20: 74 29 29.0 | F20: 30 | P20: 26.85 | Q20: 27.7 | R20: =P20-Q20 -> -0.85 | S20: 28.1 | T20: 26.7 | U20: =S20-T20 -> 1.4 | V20: 28.5 | W20: =V20-T20 -> 1.8
A21: 19 | B21: Doomara | C21: Sh. Girdhari lal/Poosa ji | D21: 26 22 0.09 | E21: 74 34 49.1 | F21: 30 | P21: 4.85 | Q21: 5.9 | R21: =P21-Q21 -> -1.05 | S21: 7.6 | T21: 4.35 | U21: =S21-T21 -> 3.25 | V21: 6.8 | W21: =V21-T21 -> 2.45
A22: 20 | B22: Fatehpur | C22: In front of primary school (Budha ji,Ratna ji,Mithuji) | D22: 26 24 45.2 | E22: 74 24 75.1 | F22: 30 | P22: 22.9 | Q22: 20.1 | R22: =P22-Q22 -> 2.8 | S22: 20.1 | T22: 19.6 | U22: =S22-T22 -> 0.5 | V22: 21.1 | W22: =V22-T22 -> 1.5
A23: 21 | B23: Jaswantpura | C23: Sh. Bheekaram /Jawahar lal ji Raigar | D23: 26 27 21.2 | E23: 74 25 56.7 | F23: 31.5 | P23: 24.1 | Q23: 30 | R23: =P23-Q23 -> -5.9 | U23: =S23-T23 -> 0
A24: 22 | B24: khori | C24: Sh. Sravan ji /Heera ji Rawat | D24: 26 34 00.9 | E24: 74 35 46.9 | F24: 52 | P24: 47.34 | Q24: 46.5 | R24: =P24-Q24 -> 0.84 | S24: 51.2 | T24: 44.3 | U24: =S24-T24 -> 6.9 | V24: 45.5 | W24: =V24-T24 -> 1.2
A25: 23 | B25: Kishanpura | C25: Sh. Mahesh ji/Omprakash ji Khateek | D25: 26 29 22.4 | E25: 74 29 01.3 | F25: 33 | P25: 21.1 | Q25: 26.5 | R25: =P25-Q25 -> -5.4 | S25: 27.4 | T25: 25.6 | U25: =S25-T25 -> 1.8 | V25: 26.34 | W25: =V25-T25 -> 0.74
A26: 24 | B26: Nathuthala | C26: Sh.Kalu Ji /Mishri ji Raigar | D26: 26 22 00.4 | E26: 74 30 02.6 | F26: 20 | P26: 8 | Q26: 2.25 | R26: =P26-Q26 -> 5.75 | S26: 5.3 | T26: 1.1 | U26: =S26-T26 -> 4.2 | V26: 2.3 | W26: =V26-T26 -> 1.2
A27: 25 | B27: Nooriyawas | C27: Shri Bhenru lal Ji /Deva Ji Gurjar | D27: 26 21 01.4 | E27: 74 29 11.6 | F27: 30 | P27: 9.2 | Q27: 4.9 | R27: =P27-Q27 -> 4.3 | S27: 18.4 | T27: 12.5 | U27: =S27-T27 -> 5.9 | V27: 14.85 | W27: =V27-T27 -> 2.35
A28: 26 | B28: Rampura Dabla | C28: Sh Kana ji/Mishri ji Jat | D28: 26 23 33.5 | E28: 74 24 59.6 | F28: 31 | P28: 27 | Q28: 27.9 | R28: =P28-Q28 -> -0.9 | S28: 27.8 | T28: 25.6 | U28: =S28-T28 -> 2.2 | V28: 28.2 | W28: =V28-T28 -> 2.6
A29: 28 | B29: Sethan | C29: Sh. Babu lal ji/Bodu ji Raigar | D29: 26 25 25.5 | E29: 74 24 40.3 | F29: 21 | P29: 19.9 | Q29: 16.2 | R29: =P29-Q29 -> 3.7 | S29: 16.85 | T29: 15.45 | U29: =S29-T29 -> 1.4 | V29: 16.9 | W29: =V29-T29 -> 1.45
A30: 29 | B30: Soorajkund | C30: Shri Hagam Ji /Heera Ji | D30: 26 27 39.5 | E30: 74 28 36.5 | F30: 18 | P30: 17.4 | Q30: 18 | R30: =P30-Q30 -> -0.6 | U30: =S30-T30 -> 0
A31: 30 | B31: Doongriya Khurd | C31: Sh. Ramswroop /Rodu lal ji Raigar | D31: 26 33 04.2 | E31: 74 33 02.7 | F31: 31.5 | P31: 30.7 | Q31: 28.6 | R31: =P31-Q31 -> 2.1 | S31: 29.95 | T31: 25.5 | U31: =S31-T31 -> 4.45 | V31: 27.5 | W31: =V31-T31 -> 2
A32: 31 | B32: Kalesra | C32: Public well | D32: 26 20 34.1 | E32: 74 25 19.2 | F32: 13.5 | P32: 7.9 | Q32: 10 | R32: =P32-Q32 -> -2.1 | S32: 12.9 | T32: 8.6 | U32: =S32-T32 -> 4.3 | V32: 10.8 | W32: =V32-T32 -> 2.2
A33: 32 | B33: Dantra | C33: Shri Harji /Lala ji Jat | D33: 26 20 14.1 | E33: 74 28 30.9 | F33: 30 | P33: 8.24 | Q33: 10 | R33: =P33-Q33 -> -1.76 | S33: 9.95 | T33: 7 | U33: =S33-T33 -> 2.95 | V33: 8.5 | W33: =V33-T33 -> 1.5
A34: 33 | B34: Govind Garh | C34: Sh.Naina ji/Ganesh ji Kumawat | D34: 26 27 22.9 | E34: 74 23 22.9 | F34: 18 | P34: 13.7 | Q34: 13.9 | R34: =P34-Q34 -> -0.2 | S34: 13.8 | T34: 12.9 | U34: =S34-T34 -> 0.9 | V34: 13.5 | W34: =V34-T34 -> 0.6
A35: 34 | B35: Lyali khera | C35: Shri Balu ji/Laxman ji Rawat | D35: 26 19 05.9 | E35: 74 27 09.2 | F35: 16.8 | P35: 11.5 | Q35: 8.6 | R35: =P35-Q35 -> 2.9 | S35: 13.95 | T35: 12.75 | U35: =S35-T35 -> 1.2 | V35: 13.6 | W35: =V35-T35 -> 0.85
A36: 35 | B36: Saradhana | C36: Sh.Ganpat ji/Suraj ji | D36: 26 21 54.7 | E36: 74 35 14.6 | F36: 30 | P36: 25.85 | Q36: 28.2 | R36: =P36-Q36 -> -2.35 | S36: 29.4 | T36: 25.2 | U36: =S36-T36 -> 4.2 | V36: 27.95 | W36: =V36-T36 -> 2.75
A37: 37 | B37: PEESANGAN | C37: PREME KISHORE S/O SANKERLAL 8875324092 | D37: 26.421682 | E37: 74.335114 | F37: 33.15 | S37: 25.7 | T37: 17.6 | U37: =S37-T37 -> 8.1 | V37: 19.52 | W37: =V37-T37 -> 1.92
A38: 38 | B38: GOVIND GARAH | C38: SHARAN SINGH 9413692988 | D38: 26.468989 | E38: 74.36089 | F38: 23.4 | S38: 14.9 | T38: 14.65 | U38: =S38-T38 -> 0.25 | V38: 15.3 | W38: =V38-T38 -> 0.65
A39: 39 | B39: GOVIND GARAH | C39: HARI SINGH S/O RAJU PANNA | D39: 26.449547 | E39: 74.354325 | F39: 24.7 | S39: 16.25 | T39: 12.5 | U39: =S39-T39 -> 3.75 | V39: 15.81 | W39: =V39-T39 -> 3.31
A40: 40 | B40: GOVIND GARAH | C40: HAJISARWER S/O SULAIMAN 8414668615 | D40: 26.448722 | E40: 74.35525 | F40: 23.7 | S40: 15.45 | T40: 14.4 | U40: =S40-T40 -> 1.05 | V40: 16.2 | W40: =V40-T40 -> 1.8
...

Sheet MonthlyRF n
N1: TABLE-XIII
A2: BLOCKWISE BIFURCATION OF MONTHLY RAINFALL (mm) FOR MONSOON AND NON-MONSOON CYCLE
A3: FROM 2002 TO 2016 OF PEESANGAN GW CLUSTER AREA AJMER DISTRICT
A4: Months/ | B4: MONSOON PERIOD | G4: NON-MONSOON PERIOD | P4: TOTAL
A5: Years | B5: June | C5: July | D5: August | E5: Sept. | F5: Total | G5: Oct. | H5: Nov. | I5: Dec. | J5: Jan | K5: Feb. | L5: March | M5: April | N5: May | O5: Total | P5: Annual
A6: BLOCK: Pisangan
A7: 1996 | B7: 124 | C7: 144 | D7: 339 | E7: 73 | F7: =+B7+C7+D7+E7 -> 680 | G7: 0 | H7: 0 | I7: 0 | J7: 0 | K7: 0 | L7: 0 | M7: 0 | N7: 0 | O7: =SUM(G7:N7) -> 0 | P7: =+F7+O7 -> 680
A8: 1997 | B8: 149 | C8: 104 | D8: 231 | E8: 63 | F8: =+B8+C8+D8+E8 -> 547 | G8: 40 | H8: 13 | M8: 43 | N8: 40 | O8: =SUM(G8:N8) -> 136 | P8: =+F8+O8 -> 683
A9: 1998 | B9: 33 | C9: 153 | D9: 89 | E9: 156 | F9: =+B9+C9+D9+E9 -> 431 | G9: 28 | L9: 7 | O9: =SUM(G9:N9) -> 35 | P9: =+F9+O9 -> 466
A10: 1999 | B10: 46 | C10: 101 | D10: 84 | E10: 41 | F10: =+B10+C10+D10+E10 -> 272 | G10: 5 | K10: 8 | O10: =SUM(G10:N10) -> 13 | P10: =+F10+O10 -> 285
A11: 2000 | B11: 0 | C11: 264 | D11: 31 | E11: 91 | F11: =+B11+C11+D11+E11 -> 386 | N11: 17 | O11: =SUM(G11:N11) -> 17 | P11: =+F11+O11 -> 403
A12: 2001 | B12: 71 | C12: 421 | D12: 177 | E12: 0 | F12: =+B12+C12+D12+E12 -> 669 | G12: 0 | H12: 0 | I12: 0 | J12: 0 | K12: 0 | L12: 0 | M12: 0 | N12: 0 | O12: =SUM(G12:N12) -> 0 | P12: =+F12+O12 -> 669
A13: 2002 | B13: 13 | C13: 0 | D13: 41 | E13: 49 | F13: =+B13+C13+D13+E13 -> 103 | K13: 30 | N13: 9 | O13: =SUM(G13:N13) -> 39 | P13: =+F13+O13 -> 142
A14: 2003 | B14: 56 | C14: 182 | D14: 102 | E14: 33 | F14: =+B14+C14+D14+E14 -> 373 | K14: 20 | O14: =SUM(G14:N14) -> 20 | P14: =+F14+O14 -> 393
A15: 2004 | B15: 0 | C15: 92 | D15: 159 | E15: 17 | F15: =+B15+C15+D15+E15 -> 268 | G15: 26 | N15: 12 | O15: =SUM(G15:N15) -> 38 | P15: =+F15+O15 -> 306
A16: 2005 | B16: 14 | C16: 172 | D16: 55 | E16: 240 | F16: =+B16+C16+D16+E16 -> 481 | L16: 11 | M16: 15 | O16: =SUM(G16:N16) -> 26 | P16: =+F16+O16 -> 507
A17: 2006 | B17: 57 | C17: 76 | D17: 126 | E17: 39 | F17: =+B17+C17+D17+E17 -> 298 | N17: 2.5 | O17: =SUM(G17:N17) -> 2.5 | P17: =+F17+O17 -> 300.5
A18: 2007 | B18: 54 | C18: 196 | D18: 92 | E18: 35 | F18: =+B18+C18+D18+E18 -> 377 | L18: 16 | O18: =SUM(G18:N18) -> 16 | P18: =+F18+O18 -> 393
A19: 2008 | B19: 48 | C19: 114 | D19: 140 | E19: 6 | F19: =+B19+C19+D19+E19 -> 308 | G19: 1 | M19: 26 | N19: 26 | O19: =SUM(G19:N19) -> 53 | P19: =+F19+O19 -> 361
A20: 2009 | B20: 10 | C20: 76 | D20: 29 | E20: 8 | F20: =+B20+C20+D20+E20 -> 123 | L20: 2 | N20: 2 | O20: =SUM(G20:N20) -> 4 | P20: =+F20+O20 -> 127
A21: 2010 | B21: 1 | C21: 85 | D21: 349 | E21: 278 | F21: =+B21+C21+D21+E21 -> 713 | H21: 85 | I21: 9 | K21: 2 | M21: 10 | O21: =SUM(G21:N21) -> 106 | P21: =+F21+O21 -> 819
A22: 2011 | B22: 66 | C22: 86 | D22: 193 | E22: 209 | F22: =+B22+C22+D22+E22 -> 554 | G22: 0 | H22: 0 | I22: 0 | J22: 0 | K22: 28 | L22: 0 | M22: 0 | N22: 0 | O22: =SUM(G22:N22) -> 28 | P22: =+F22+O22 -> 582
A23: 2012 | B23: 0 | C23: 126 | D23: 391.5 | E23: 59.5 | F23: =+B23+C23+D23+E23 -> 577 | N23: 30 | O23: =SUM(G23:N23) -> 30 | P23: =+F23+O23 -> 607
A24: 2013 | B24: 6 | C24: 81.5 | D24: 116 | E24: 199 | F24: =+B24+C24+D24+E24 -> 402.5 | J24: 4 | K24: 15 | O24: =SUM(G24:N24) -> 19 | P24: =+F24+O24 -> 421.5
A25: 2014 | B25: 3 | C25: 92 | D25: 429 | E25: 110 | F25: =+B25+C25+D25+E25 -> 634 | J25: 3 | K25: 3 | L25: 6 | M25: 13 | N25: 17 | O25: =SUM(G25:N25) -> 42 | P25: =+F25+O25 -> 676
A26: 2015 | B26: 114 | C26: 186.5 | D26: 42 | E26: 8 | F26: =+B26+C26+D26+E26 -> 350.5 | J26: 15 | K26: 5 | L26: 42 | M26: 22 | O26: =SUM(G26:N26) -> 84 | P26: =+F26+O26 -> 434.5
A27: 2016 | B27: 63 | C27: 99 | D27: 420.5 | E27: 25 | F27: =+B27+C27+D27+E27 -> 607.5 | G27: 58 | L27: 2 | O27: =SUM(G27:N27) -> 60 | P27: =+F27+O27 -> 667.5
A28: Average(2007-2016) | F28: =AVERAGE(F18:F27) -> 464.65 | O28: =AVERAGE(O18:O27) -> 44.2 | P28: =AVERAGE(P18:P27) -> 508.85

Sheet NormalRF
A2: TABLE - XI : SHOWING MONSOON & NON-MONSOON RAINFALL (2012-16)
M3: Unit : mm
A4: S. No. | B4: BLOCKS | C4: 2012 | E4: 2013 | G4: 2014 | I4: 2015 | K4: 2016 | M4: Normal Non-Monsoon rainfall | N4: Normal Annual rainfall
C5: Normal Monsoon Rainfall | D5: Monsoon Rainfall | E5: Normal Monsoon Rainfall | F5: Monsoon Rainfall | G5: Normal Monsoon Rainfall | H5: Monsoon Rainfall | I5: Normal Monsoon Rainfall | J5: Monsoon Rainfall | K5: Normal Monsoon Rainfall | L5: Monsoon Rainfall
A6: 1 | B6: PISANGAN | C6: 393.02 | D6: ='MonthlyRF n'!F23 -> 577 | E6: 393.5 | F6: ='MonthlyRF n'!F24 -> 402.5 | G6: 398.93 | H6: =I5 -> Normal Monsoon Rainfall | I6: 399.03 | J6: ='MonthlyRF n'!F26 -> 350.5 | K6: 403.47 | L6: ='MonthlyRF n'!F27 -> 607.5 | M6: 40.58 | N6: =SUM(K6,M6) -> 444.05
A8: Note: Rain Fall data available from 1957

Sheet Longterm
A2: PEESANGAN | E2: Zone-Ao
A3: YEAR | B3: ANNUAL | C3: MONSOON | D3: PRE | E3: POST
A4: 2007 | B4: ='MonthlyRF n'!P18 -> 393 | C4: ='MonthlyRF n'!F18 -> 377 | D4: ='WaterLevel trend'!G12 -> 18.69125 | E4: ='WaterLevel trend'!R12 -> 17.2625
A5: 2008 | B5: ='MonthlyRF n'!P19 -> 361 | C5: ='MonthlyRF n'!F19 -> 308 | D5: ='WaterLevel trend'!H12 -> 24.45625 | E5: ='WaterLevel trend'!S12 -> 22.0675
A6: 2009 | B6: ='MonthlyRF n'!P20 -> 127 | C6: ='MonthlyRF n'!F20 -> 123 | D6: ='WaterLevel trend'!I12 -> 26.11625 | E6: ='WaterLevel trend'!T12 -> 26.9525
A7: 2010 | B7: ='MonthlyRF n'!P21 -> 819 | C7: ='MonthlyRF n'!F21 -> 713 | D7: ='WaterLevel trend'!J12 -> 27.2475 | E7: ='WaterLevel trend'!U12 -> 24.97375
A8: 2011 | B8: ='MonthlyRF n'!P22 -> 582 | C8: ='MonthlyRF n'!F22 -> 554 | D8: ='WaterLevel trend'!K12 -> 25.24375 | E8: ='WaterLevel trend'!V12 -> 22.11
A9: 2012 | B9: ='MonthlyRF n'!P23 -> 607 | C9: ='MonthlyRF n'!F23 -> 577 | D9: ='WaterLevel trend'!L12 -> 24.76625 | E9: ='WaterLevel trend'!W12 -> 21.9475
A10: 2013 | B10: ='MonthlyRF n'!P24 -> 421.5 | C10: ='MonthlyRF n'!F24 -> 402.5 | D10: ='WaterLevel trend'!M12 -> 23.80625 | E10: ='WaterLevel trend'!X12 -> 23.65125
A11: 2014 | B11: ='MonthlyRF n'!P25 -> 676 | C11: ='MonthlyRF n'!F25 -> 634 | D11: ='WaterLevel trend'!N12 -> 24.77 | E11: ='WaterLevel trend'!Y12 -> 23.11875
A12: 2015 | B12: ='MonthlyRF n'!P26 -> 434.5 | C12: ='MonthlyRF n'!F26 -> 350.5 | D12: ='WaterLevel trend'!O12 -> 25.53375 | E12: ='WaterLevel trend'!Z12 -> 24.2675
A13: 2016 | B13: ='MonthlyRF n'!P27 -> 667.5 | C13: ='MonthlyRF n'!F27 -> 607.5 | D13: ='WaterLevel trend'!P12 -> 26.20625 | E13: ='WaterLevel trend'!AA12 -> 24.71375

Sheet Trend 
A1: COMPUTATION FOR TREND OF WATER LEVELS FOR THE PERIOD 2007-2016 IN PEESANGAN GW CLUSTER OF AJMER DISTRICT
A4: Year | B4: No | C4: Average Pre-Mon. W.L. (m) | D4: Average Post-mon. W.L. (m.) | H4: Value "a" for Pre-Mon. W.L. | I4: Value "a" for Post-mon. W.L.
B5: X1 | C5: Y1 | D5: Y2 | E5: X1^2 | F5: X1*Y1 | G5: X1*Y2 | H5: "a"- pre | I5: "a" -post
A6: BLOCK : PISANGAN | D6: ZONE-A
A7: =[2]Longterm!A4 -> 2007 | B7: 1 | C7: =Longterm!$D$4 -> 18.69125 | D7: =Longterm!$E$4 -> 17.2625 | E7: =B7*B7 -> 1 | F7: =B7*C7 -> 18.69125 | G7: =B7*D7 -> 17.2625
A8: =[2]Longterm!A5 -> 2008 | B8: 2 | C8: =Longterm!$D$5 -> 24.45625 | D8: =Longterm!$E$5 -> 22.0675 | E8: =B8*B8 -> 4 | F8: =B8*C8 -> 48.9125 | G8: =B8*D8 -> 44.135
A9: =[2]Longterm!A6 -> 2009 | B9: 3 | C9: =Longterm!$D$6 -> 26.11625 | D9: =Longterm!$E$6 -> 26.9525 | E9: =B9*B9 -> 9 | F9: =B9*C9 -> 78.34875 | G9: =B9*D9 -> 80.8575
A10: =[2]Longterm!A7 -> 2010 | B10: 4 | C10: =Longterm!$D$7 -> 27.2475 | D10: =Longterm!$E$7 -> 24.97375 | E10: =B10*B10 -> 16 | F10: =B10*C10 -> 108.99 | G10: =B10*D10 -> 99.895
A11: =[2]Longterm!A8 -> 2011 | B11: 5 | C11: =Longterm!$D$8 -> 25.24375 | D11: =Longterm!$E$8 -> 22.11 | E11: =B11*B11 -> 25 | F11: =B11*C11 -> 126.21875 | G11: =B11*D11 -> 110.55
A12: =[2]Longterm!A9 -> 2012 | B12: 6 | C12: =Longterm!$D$9 -> 24.76625 | D12: =Longterm!$E$9 -> 21.9475 | E12: =B12*B12 -> 36 | F12: =B12*C12 -> 148.5975 | G12: =B12*D12 -> 131.685
A13: =[2]Longterm!A10 -> 2013 | B13: 7 | C13: =Longterm!$D$10 -> 23.80625 | D13: =Longterm!$E$10 -> 23.65125 | E13: =B13*B13 -> 49 | F13: =B13*C13 -> 166.64375 | G13: =B13*D13 -> 165.55875
